Workbook
Name CompanyName: YourCFOGuy
Name CS: CS!$B$4:$AN$53
Name CS_Budget: CS_Budget!$B$4:$AN$53
Name CurrentMonth: List!$W$3
Name GandA: 'G&A'!$B$4:$AN$53
Name GandA_Budget: 'G&A_Budget'!$B$4:$AN$53
Name RandD: 'R&D'!$B$4:$AN$53
Name RandD_Budget: 'R&D_Budget'!$B$4:$AN$53
Name SandM: 'S&M'!$B$4:$AN$53
Name SandM_Budget: 'S&M_Budget'!$B$4:$AN$53
Name Slicer_Period: #N/A
Name StartDate: 44227

Sheet Instructions
D5: The Ultimate Dashboard
D11: Legal Disclaimer | L11: 3 Ways I can help you | U11: Instructions
A13: This document is provided as a reference and template, and the financial information included should not be considered a certified business valuation, or projection. The information provided by Your CFO Guy (“we,” “us” or “our”) on https://yourcfoguy.com (the “Site”) is for general informational purposes only. All information on the Site is provided in good faith, however we make no representation or warranty of any kind, express or implied, regarding the accuracy, adequacy, validity, reliability, availability or completeness of any information on the Site. UNDER NO CIRCUMSTANCE SHALL WE HAVE ANY LIABILITY TO YOU FOR ANY LOSS OR DAMAGE OF ANY KIND INCURRED AS A RESULT OF THE USE OF THE SITE OR RELIANCE ON ANY INFORMATION PROVIDED ON THE SITE. YOUR USE OF THE SITE AND YOUR RELIANCE ON ANY INFORMATION ON THE SITE IS SOLELY AT YOUR OWN RISK. The Site cannot and does not contain financial advice. The financial information is provided for general informational and educational purposes only and is not a substitute for professional advice. Accordingly, before taking any actions based upon such information, we encourage you to consult with the appropriate professionals. We do not provide any kind of financial advice. THE USE OR RELIANCE OF ANY INFORMATION CONTAINED ON THIS SITE IS SOLELY AT YOUR OWN RISK. | J13: #VALUE! | K13: Take control of your Finance & Accounting Function | S13: #VALUE! | T13: Watch the full YouTube video here
J16: Click Here | S16: #VALUE! | T16: s
J20: #VALUE! | K20: Get Access to 100+ Finance & Accounting Templates | S20: To get started, Click File > Save As > Download a Copy
J23: Click Here
J27: #VALUE! | K27: Work with me 1-on-1
J30: Book Now

Sheet Dashboard
C1: FINANCIAL DASHBOARD
B2: #VALUE! | O2: BY DEPARTMENT | W2: BY COST
B18: vs BUDGET | O18: BY DEPARTMENT | S18: Budget | T18: Actual | U18: ▲ | V18: % | W18: BY COST | AA18: Budget | AB18: Actual | AC18: ▲ | AD18: %
O19: Customer Support | S19: =Data!V10 -> 151803.75 | T19: =Data!W10 -> 82873.122 | U19: =Data!X10 -> 68930.629 | V19: =Data!Y10 -> 0.83176098 | W19: Advertising | AA19: =Data!AB10 -> 245241.11 | AB19: =Data!AC10 -> 130260.72 | AC19: =Data!AD10 -> 114980.39 | AD19: =IFERROR(AC19/ABS(AA19),0) -> 0.46884633
O21: General & Administrative | S21: =Data!V11 -> 248464.66 | T21: =Data!W11 -> 219330.2 | U21: =Data!X11 -> 29134.464 | V21: =Data!Y12 -> 0.19509478 | W21: Other G&A | AA21: =Data!AB11 -> 292884.35 | AB21: =Data!AC11 -> 212909.19 | AC21: =Data!AD11 -> 79975.166 | AD21: =IFERROR(AC21/ABS(AA21),0) -> 0.27306056
B22: REVENUE | E22: =Data!Q49 -> GROSS PROFIT | H22: =Data!R49 -> EBITDA
O23: Research & Development | S23: =Data!V12 -> 184162.14 | T23: =Data!W12 -> 154098.36 | U23: =Data!X12 -> 30063.785 | V23: =Data!Y14 -> 0.31934681 | W23: Payroll | AA23: =Data!AB12 -> 327740.25 | AB23: =Data!AC12 -> 264464.02 | AC23: =Data!AD12 -> 63276.23 | AD23: =IFERROR(AC23/ABS(AA23),0) -> 0.19306823
B24: =Data!P57 -> -5122.1619 | E24: =Data!Q57 -> -123182.38 | H24: =Data!R57 -> 104879.22
O25: Sales & Marketing | S25: =Data!V13 -> 357781.28 | T25: =Data!W13 -> 257848.56 | U25: =Data!X13 -> 99932.721 | V25: =Data!Y16 -> 0 | W25: Professional Fees | AA25: =Data!AB13 -> 76346.124 | AB25: =Data!AC13 -> 106516.31 | AC25: =Data!AD13 -> -30170.189 | AD25: =IFERROR(AC25/ABS(AA25),0) -> -0.39517644
O27: Total | S27: =SUM(S19:S26) -> 942211.83 | T27: =SUM(T19:T26) -> 714150.23 | U27: =SUM(U19:U26) -> 228061.6 | V27: =IFERROR(U27/ABS(S27),0) -> 0.24204918 | W27: Total | AA27: =SUM(AA19:AA26) -> 942211.83 | AB27: =SUM(AB19:AB26) -> 714150.23 | AC27: =SUM(AC19:AC26) -> 228061.6 | AD27: =IFERROR(AC27/ABS(AA27),0) -> 0.24204918
B29: vs PRIOR PERIOD | O29: BY DEPARTMENT | S29: Prior Period | T29: Actual | U29: ▲ | V29: % | W29: BY COST | AA29: Prior Period | AB29: Actual | AC29: ▲ | AD29: %
O30: Customer Support | S30: =Data!V20 -> 74262.567 | T30: =Data!W20 -> 82873.122 | U30: =Data!X20 -> 8610.5548 | V30: =Data!Y20 -> 0.11594744 | W30: Advertising | AA30: =Data!AB20 -> 146366.51 | AB30: =Data!AC20 -> 130260.72 | AC30: =Data!AD20 -> -16105.797 | AD30: =IFERROR(AC30/ABS(AA30),0) -> -0.11003744
O32: General & Administrative | S32: =Data!V21 -> 191874.76 | T32: =Data!W21 -> 219330.2 | U32: =Data!X21 -> 27455.436 | V32: =Data!Y22 -> 0.069685313 | W32: Other G&A | AA32: =Data!AB21 -> 184365.17 | AB32: =Data!AC21 -> 212909.19 | AC32: =Data!AD21 -> 28544.018 | AD32: =IFERROR(AC32/ABS(AA32),0) -> 0.15482327
O34: Research & Development | S34: =Data!V22 -> 144059.52 | T34: =Data!W22 -> 154098.36 | U34: =Data!X22 -> 10038.833 | V34: =Data!Y24 -> 0.044268743 | W34: Payroll | AA34: =Data!AB22 -> 255693.73 | AB34: =Data!AC22 -> 264464.02 | AC34: =Data!AD22 -> 8770.2849 | AD34: =IFERROR(AC34/ABS(AA34),0) -> 0.03429996
O36: Sales & Marketing | S36: =Data!V23 -> 273679.06 | T36: =Data!W23 -> 257848.56 | U36: =Data!X23 -> -15830.497 | V36: =Data!Y27 -> 0 | W36: Professional Fees | AA36: =Data!AB23 -> 97450.493 | AB36: =Data!AC23 -> 106516.31 | AC36: =Data!AD23 -> 9065.8206 | AD36: =IFERROR(AC36/ABS(AA36),0) -> 0.093030013
O38: Total | S38: =SUM(S30:S37) -> 683875.91 | T38: =SUM(T30:T37) -> 714150.23 | U38: =SUM(U30:U37) -> 30274.327 | V38: =IFERROR(U38/ABS(S38),0) -> 0.044268743 | W38: Total | AA38: =SUM(AA30:AA37) -> 683875.91 | AB38: =SUM(AB30:AB37) -> 714150.23 | AC38: =SUM(AC30:AC37) -> 30274.327 | AD38: =IFERROR(AC38/ABS(AA38),0) -> 0.044268743
B40: vs PRIOR YEAR | O40: BY DEPARTMENT | S40: Prior Year | T40: Actual | U40: ▲ | V40: % | W40: BY COST | AA40: Prior Year | AB40: Actual | AC40: ▲ | AD40: %
O41: Customer Support | S41: =Data!V30 -> 73148.433 | T41: =Data!W30 -> 82873.122 | U41: =Data!X30 -> 9724.689 | V41: =Data!Y30 -> 0.1329446 | W41: Advertising | AA41: =Data!AB30 -> 144548.59 | AB41: =Data!AC30 -> 130260.72 | AC41: =Data!AD30 -> -14287.872 | AD41: =IFERROR(AC41/ABS(AA41),0) -> -0.098844772
O43: General & Administrative | S43: =Data!V31 -> 179360.63 | T43: =Data!W31 -> 219330.2 | U43: =Data!X31 -> 39969.57 | V43: =Data!Y32 -> 0.14926387 | W43: Other G&A | AA43: =Data!AB31 -> 170315.51 | AB43: =Data!AC31 -> 212909.19 | AC43: =Data!AD31 -> 42593.677 | AD43: =IFERROR(AC43/ABS(AA43),0) -> 0.2500869
O45: Research & Development | S45: =Data!V32 -> 134084.4 | T45: =Data!W32 -> 154098.36 | U45: =Data!X32 -> 20013.956 | V45: =Data!Y34 -> 0.065764798 | W45: Payroll | AA45: =Data!AB32 -> 263571.97 | AB45: =Data!AC32 -> 264464.02 | AC45: =Data!AD32 -> 892.04467 | AD45: =IFERROR(AC45/ABS(AA45),0) -> 0.0033844444
O47: Sales & Marketing | S47: =Data!V33 -> 283488.94 | T47: =Data!W33 -> 257848.56 | U47: =Data!X33 -> -25640.381 | V47: =Data!Y37 -> 0 | W47: Professional Fees | AA47: =Data!AB33 -> 91646.33 | AB47: =Data!AC33 -> 106516.31 | AC47: =Data!AD33 -> 14869.984 | AD47: =IFERROR(AC47/ABS(AA47),0) -> 0.162254
O49: Total | S49: =SUM(S41:S48) -> 670082.4 | T49: =SUM(T41:T48) -> 714150.23 | U49: =SUM(U41:U48) -> 44067.834 | V49: =IFERROR(U49/ABS(S49),0) -> 0.065764798 | W49: Total | AA49: =SUM(AA41:AA48) -> 670082.4 | AB49: =SUM(AB41:AB48) -> 714150.23 | AC49: =SUM(AC41:AC48) -> 44067.834 | AD49: =IFERROR(AC49/ABS(AA49),0) -> 0.065764798

Sheet Data
F6: Section | G6: Expenses | AG6: Section | AH6: Expenses | AP6: Departments | AQ6: All
O7: Section | P7: (Multiple Items) | U7: Section | V7: Expenses | AA7: Section | AB7: Expenses
AP8: P&L | AQ8: Actual
B9: Revenue & Gross Margin | C9: Revenue | D9: Gross margin | G9: Customer Support | H9: General & Administrative | I9: Research & Development | J9: Sales & Marketing | L9: Section | M9: Expenses | O9: BvA: Rev, GP, EBITDA | P9: Budget | Q9: Actual | R9: Var to Budget Income ($) | S9: Var to Budget Income (%) | U9: BvA: Opex By Dept | V9: Budget | W9: Actual | X9: Var to Budget Expense ($) | Y9: Var to Budget Expense (%) | AA9: BvA: Opex By Cost Type | AB9: Budget | AC9: Actual | AD9: Var to Budget Expense ($) | AE9: Var to Budget Expense (%) | AH9: Customer Support | AI9: General & Administrative | AJ9: Research & Development | AK9: Sales & Marketing | AM9: Section | AN9: Expenses | AP9: Income | AQ9: 801118.03
B10: Jan-24 | C10: 112146.24 | D10: 0.87300372 | F10: Jan-24 | G10: 11405.29 | H10: 30761.505 | I10: 21048.484 | J10: 36671.753 | O10: Revenue | P10: 806240.19 | Q10: 801118.03 | R10: -5122.1619 | S10: -0.0063937669 | U10: Customer Support | V10: 151803.75 | W10: 82873.122 | X10: 68930.629 | Y10: 0.83176098 | AA10: Advertising | AB10: 245241.11 | AC10: 130260.72 | AD10: 114980.39 | AE10: 0.88269431 | AG10: Jan-24 | AH10: 11405.29 | AI10: 30761.505 | AJ10: 21048.484 | AK10: 36671.753 | AP10: Cost of Goods Sold | AQ10: 141454.25
B11: Feb-24 | C11: 115510.63 | D11: 0.81252824 | F11: Feb-24 | G11: 11747.449 | H11: 30146.275 | I11: 21358.44 | J11: 37609.95 | O11: Gross Profit | P11: 782846.16 | Q11: 659663.78 | R11: -123182.38 | S11: -0.18673509 | U11: General & Administrative | V11: 248464.66 | W11: 219330.2 | X11: 29134.464 | Y11: 0.1328338 | AA11: Other G&A | AB11: 292884.35 | AC11: 212909.19 | AD11: 79975.166 | AE11: 0.37563041 | AG11: Feb-24 | AH11: 11747.449 | AI11: 30146.275 | AJ11: 21358.44 | AK11: 37609.95 | AP11: Gross Profit | AQ11: 659663.78
B12: Mar-24 | C12: 112045.31 | D12: 0.85152687 | F12: Mar-24 | G12: 11777.678 | H12: 30578.689 | I12: 21709.845 | J12: 37645.05 | L12: Customer Support | M12: 82873.122 | O12: EBITDA | P12: -159365.67 | Q12: -54486.453 | R12: 104879.22 | S12: 1.9248679 | U12: Research & Development | V12: 184162.14 | W12: 154098.36 | X12: 30063.785 | Y12: 0.19509478 | AA12: Payroll | AB12: 327740.25 | AC12: 264464.02 | AD12: 63276.23 | AE12: 0.23926215 | AG12: Mar-24 | AH12: 11777.678 | AI12: 30578.689 | AJ12: 21709.845 | AK12: 37645.05 | AM12: Customer Support | AN12: 82873.122 | AP12: Expenses | AQ12: 714150.23
B13: Apr-24 | C13: 115406.67 | D13: 0.75095103 | F13: Apr-24 | G13: 11834.589 | H13: 31094.819 | I13: 22361.14 | J13: 38118.482 | L13: General & Administrative | M13: 219330.2 | O13: Grand Total | P13: 1429720.7 | Q13: 1406295.4 | R13: -23425.317 | S13: -0.016657466 | U13: Sales & Marketing | V13: 357781.28 | W13: 257848.56 | X13: 99932.721 | Y13: 0.38756362 | AA13: Professional Fees | AB13: 76346.124 | AC13: 106516.31 | AD13: -30170.189 | AE13: -0.28324478 | AG13: Apr-24 | AH13: 11834.589 | AI13: 31094.819 | AJ13: 22361.14 | AK13: 38118.482 | AM13: General & Administrative | AN13: 219330.2 | AP13: Advertising | AQ13: 130260.72
B14: May-24 | C14: 111944.47 | D14: 0.81973828 | F14: May-24 | G14: 12189.627 | H14: 32277.813 | I14: 22722.701 | J14: 36197.416 | L14: Research & Development | M14: 154098.36 | U14: Grand Total | V14: 942211.83 | W14: 714150.23 | X14: 228061.6 | Y14: 0.31934681 | AA14: Grand Total | AB14: 942211.83 | AC14: 714150.23 | AD14: 228061.6 | AE14: 0.31934681 | AG14: May-24 | AH14: 12189.627 | AI14: 32277.813 | AJ14: 22722.701 | AK14: 36197.416 | AM14: Research & Development | AN14: 154098.36 | AP14: Advertising & Marketing | AQ14: 80711.767
B15: Jun-24 | C15: 115302.81 | D15: 0.79904088 | F15: Jun-24 | G15: 12023.519 | H15: 31632.257 | I15: 23128.109 | J15: 35273.847 | L15: Sales & Marketing | M15: 257848.56 | AG15: Jun-24 | AH15: 12023.519 | AI15: 31632.257 | AJ15: 23128.109 | AK15: 35273.847 | AM15: Sales & Marketing | AN15: 257848.56 | AP15: Conferences & Events | AQ15: 49548.948
B16: Jul-24 | C16: 118761.89 | D16: 0.85829608 | F16: Jul-24 | G16: 11894.971 | H16: 32838.839 | I16: 21769.637 | J16: 36332.063 | L16: Grand Total | M16: 714150.23 | AG16: Jul-24 | AH16: 11894.971 | AI16: 32838.839 | AJ16: 21769.637 | AK16: 36332.063 | AM16: Grand Total | AN16: 714150.23 | AP16: Other G&A | AQ16: 212909.19
O17: Section | P17: (Multiple Items) | U17: Section | V17: Expenses | AA17: Section | AB17: Expenses | AP17: Payroll | AQ17: 264464.02
AP18: Professional Fees | AQ18: 106516.31
O19: AvPP: Rev, GP, EBITDA | P19: Prior Period | Q19: Actual | R19: Var to Prior Period ($) | S19: Var to Prior Period (%) | U19: AvPP: Opex By Dept | V19: Prior Period | W19: Actual | X19: Var to Prior Period ($) | Y19: Var to Prior Period (%) | AA19: AvPP: Opex By Cost Type | AB19: Prior Period | AC19: Actual | AD19: Var to Prior Period ($) | AE19: Var to Prior Period (%) | AP19: EBITDA | AQ19: -54486.453
O20: Revenue | P20: 747344.82 | Q20: 801118.03 | R20: 53773.213 | S20: 0.071952346 | U20: Customer Support | V20: 74262.567 | W20: 82873.122 | X20: 8610.5548 | Y20: 0.11594744 | AA20: Advertising | AB20: 146366.51 | AC20: 130260.72 | AD20: -16105.797 | AE20: -0.11003744 | AP20: Other Income | AQ20: 0
O21: Gross Profit | P21: 623631.09 | Q21: 659663.78 | R21: 36032.688 | S21: 0.05777885 | U21: General & Administrative | V21: 191874.76 | W21: 219330.2 | X21: 27455.436 | Y21: 0.1430904 | AA21: Other G&A | AB21: 184365.17 | AC21: 212909.19 | AD21: 28544.018 | AE21: 0.15482327 | AP21: Other Expenses | AQ21: 2067.6949
O22: EBITDA | P22: -60244.814 | Q22: -54486.453 | R22: 5758.3609 | S22: 0.095582683 | U22: Research & Development | V22: 144059.52 | W22: 154098.36 | X22: 10038.833 | Y22: 0.069685313 | AA22: Payroll | AB22: 255693.73 | AC22: 264464.02 | AD22: 8770.2849 | AE22: 0.03429996 | AP22: Interest Expense | AQ22: 74437.017
O23: Grand Total | P23: 1310731.1 | Q23: 1406295.4 | R23: 95564.261 | S23: 0.072909128 | U23: Sales & Marketing | V23: 273679.06 | W23: 257848.56 | X23: -15830.497 | Y23: -0.05784329 | AA23: Professional Fees | AB23: 97450.493 | AC23: 106516.31 | AD23: 9065.8206 | AE23: 0.093030013 | AP23: Net Other Income | AQ23: -76504.712
F24: Section | G24: Expenses | L24: Section | M24: Expenses | U24: Grand Total | V24: 683875.91 | W24: 714150.23 | X24: 30274.327 | Y24: 0.044268743 | AA24: Grand Total | AB24: 683875.91 | AC24: 714150.23 | AD24: 30274.327 | AE24: 0.044268743 | AG24: Section | AH24: Expenses | AM24: Section | AN24: Expenses | AP24: Net Income | AQ24: -130991.16
AP25: Grand Total | AQ25: 2130908.7
G27: Advertising | H27: Other G&A | I27: Payroll | J27: Professional Fees | L27: Advertising | M27: 130260.72 | O27: Section | P27: (Multiple Items) | U27: Section | V27: Expenses | AA27: Section | AB27: Expenses | AH27: Advertising | AI27: Other G&A | AJ27: Payroll | AK27: Professional Fees | AM27: Advertising | AN27: 130260.72
F28: Jan-24 | G28: 19431.892 | H28: 29529.336 | I28: 36264.882 | J28: 14660.922 | L28: Other G&A | M28: 212909.19 | AG28: Jan-24 | AH28: 19431.892 | AI28: 29529.336 | AJ28: 36264.882 | AK28: 14660.922 | AM28: Other G&A | AN28: 212909.19
F29: Feb-24 | G29: 19953.336 | H29: 29350.079 | I29: 37044.557 | J29: 14514.141 | L29: Payroll | M29: 264464.02 | O29: AvPY: Rev, GP, EBITDA | P29: Prior Year | Q29: Actual | R29: Var to Prior Year ($) | S29: Var to Prior Year (%) | U29: AvPY: Opex By Dept | V29: Prior Year | W29: Actual | X29: Var to Prior Year ($) | Y29: Var to Prior Year (%) | AA29: AvPY: Opex By Cost Type | AB29: Prior Year | AC29: Actual | AD29: Var to Prior Year ($) | AE29: Var to Prior Year (%) | AG29: Feb-24 | AH29: 19953.336 | AI29: 29350.079 | AJ29: 37044.557 | AK29: 14514.141 | AM29: Payroll | AN29: 264464.02
F30: Mar-24 | G30: 19835.193 | H30: 29407.745 | I30: 37529.781 | J30: 14938.542 | L30: Professional Fees | M30: 106516.31 | O30: Revenue | P30: 714351.19 | Q30: 801118.03 | R30: 86766.842 | S30: 0.12146244 | U30: Customer Support | V30: 73148.433 | W30: 82873.122 | X30: 9724.689 | Y30: 0.1329446 | AA30: Advertising | AB30: 144548.59 | AC30: 130260.72 | AD30: -14287.872 | AE30: -0.098844772 | AG30: Mar-24 | AH30: 19835.193 | AI30: 29407.745 | AJ30: 37529.781 | AK30: 14938.542 | AM30: Professional Fees | AN30: 106516.31
F31: Apr-24 | G31: 19786.868 | H31: 30154.32 | I31: 38092.387 | J31: 15375.455 | L31: Grand Total | M31: 714150.23 | O31: Gross Profit | P31: 558738.28 | Q31: 659663.78 | R31: 100925.5 | S31: 0.18063108 | U31: General & Administrative | V31: 179360.63 | W31: 219330.2 | X31: 39969.57 | Y31: 0.22284472 | AA31: Other G&A | AB31: 170315.51 | AC31: 212909.19 | AD31: 42593.677 | AE31: 0.2500869 | AG31: Apr-24 | AH31: 19786.868 | AI31: 30154.32 | AJ31: 38092.387 | AK31: 15375.455 | AM31: Grand Total | AN31: 714150.23
F32: May-24 | G32: 18029.407 | H32: 31227.748 | I32: 38614.425 | J32: 15515.977 | O32: EBITDA | P32: -111344.12 | Q32: -54486.453 | R32: 56857.664 | S32: 0.51064812 | U32: Research & Development | V32: 134084.4 | W32: 154098.36 | X32: 20013.956 | Y32: 0.14926387 | AA32: Payroll | AB32: 263571.97 | AC32: 264464.02 | AD32: 892.04467 | AE32: 0.0033844444 | AG32: May-24 | AH32: 18029.407 | AI32: 31227.748 | AJ32: 38614.425 | AK32: 15515.977
F33: Jun-24 | G33: 16401.45 | H33: 31067.125 | I33: 39060.712 | J33: 15528.444 | O33: Grand Total | P33: 1161745.4 | Q33: 1406295.4 | R33: 244550 | S33: 0.21050224 | U33: Sales & Marketing | V33: 283488.94 | W33: 257848.56 | X33: -25640.381 | Y33: -0.09044579 | AA33: Professional Fees | AB33: 91646.33 | AC33: 106516.31 | AD33: 14869.984 | AE33: 0.162254 | AG33: Jun-24 | AH33: 16401.45 | AI33: 31067.125 | AJ33: 39060.712 | AK33: 15528.444
F34: Jul-24 | G34: 16822.569 | H34: 32172.834 | I34: 37857.273 | J34: 15982.833 | U34: Grand Total | V34: 670082.4 | W34: 714150.23 | X34: 44067.834 | Y34: 0.065764798 | AA34: Grand Total | AB34: 670082.4 | AC34: 714150.23 | AD34: 44067.834 | AE34: 0.065764798 | AG34: Jul-24 | AH34: 16822.569 | AI34: 32172.834 | AJ34: 37857.273 | AK34: 15982.833
O35: Budget | P35: REVENUE | Q35: GROSS PROFIT | R35: EBITDA
O36: A (+) | P36: =MIN(IF(S10>0,S10,0),1) -> 0 | Q36: =MIN(IF(S11>0,S11,0),1) -> 0 | R36: =MIN(IF(S12>0,S12,0),1) -> 1
O37: B (+) | P37: =MAX(IF(S10>0,1-P36,0),0) -> 0 | Q37: =MAX(IF(S11>0,1-Q36,0),0) -> 0 | R37: =MAX(IF(S12>0,1-R36,0),0) -> 0
O38: A (-) | P38: =ABS(MIN(IF(S10<0,S10,0),1)) -> 0.0063937669 | Q38: =ABS(MIN(IF(S11<0,S11,0),1)) -> 0.18673509 | R38: =ABS(MIN(IF(S12<0,S12,0),1)) -> 0
O39: B (-) | P39: =IF(S10<0,MIN(1-P38,1),0) -> 0.99360623 | Q39: =IF(S11<0,MIN(1-Q38,1),0) -> 0.81326491 | R39: =IF(S12<0,MIN(1-R38,1),0) -> 0
O40: text | P40: =IF(P36>0,TEXT(P36,"0%")& " hit",IF(P38>0,TEXT(P38,"0%")&" miss","")) -> 1% miss | Q40: =IF(Q36>0,TEXT(Q36,"0%")& " hit",IF(Q38>0,TEXT(Q38,"0%")&" miss","")) -> 19% miss | R40: =IF(R36>0,TEXT(R36,"0%")& " hit",IF(R38>0,TEXT(R38,"0%")&" miss","")) -> 100% hit
O42: Prior Period | P42: REVENUE | Q42: GROSS PROFIT | R42: EBITDA
O43: A (+) | P43: =MIN(IF(S20>0,S20,0),1) -> 0.071952346 | Q43: =MIN(IF(S21>0,S21,0),1) -> 0.05777885 | R43: =MIN(IF(S22>0,S22,0),1) -> 0.095582683
O44: B (+) | P44: =MAX(IF(S20>0,1-P43,0),0) -> 0.92804765 | Q44: =MAX(IF(S21>0,1-Q43,0),0) -> 0.94222115 | R44: =MAX(IF(S22>0,1-R43,0),0) -> 0.90441732
O45: A (-) | P45: =ABS(MIN(IF(S20<0,S20,0),1)) -> 0 | Q45: =ABS(MIN(IF(S21<0,S21,0),1)) -> 0 | R45: =ABS(MIN(IF(S22<0,S22,0),1)) -> 0
O46: B (-) | P46: =IF(S20<0,MIN(1-P45,1),0) -> 0 | Q46: =IF(S21<0,MIN(1-Q45,1),0) -> 0 | R46: =IF(S22<0,MIN(1-R45,1),0) -> 0
O47: text | P47: =IF(P43>0,TEXT(P43,"0%")& " hit",IF(P45>0,TEXT(P45,"0%")&" miss","")) -> 7% hit | Q47: =IF(Q43>0,TEXT(Q43,"0%")& " hit",IF(Q45>0,TEXT(Q45,"0%")&" miss","")) -> 6% hit | R47: =IF(R43>0,TEXT(R43,"0%")& " hit",IF(R45>0,TEXT(R45,"0%")&" miss","")) -> 10% hit
...

Sheet List
B2: Departments | D2: Summary Groupings | F2: Metrics | H2: Versions | J2: Files | L2: Period | N2: Account | O2: Section | P2: Summary Grouping | Q2: Sign | S2: Period | T2: Date | V2: Metric | W2: Amount | Y2: Section | Z2: Sign
B3: Customer Support | D3: Revenue | F3: Revenue | H3: Actual | J3: =2*4 -> 8 | L3: 2023 | N3: Revenue | O3: Income | P3: Revenue | Q3: 1 | S3: 2023 Start | T3: 44927 | V3: Current Month | W3: 45504 | Y3: Income | Z3: 1
B4: General & Administrative | D4: COGS | F4: COGS | H4: Budget | L4: 2024 | N4: Sales | O4: Income | P4: Revenue | Q4: 1 | S4: 2023 End | T4: 45291 | Y4: Cost of Goods Sold | Z4: -1
B5: Research & Development | D5: Gross Profit | F5: Gross Profit | L5: 2025 | N5: Cost of Goods Sold | O5: Cost of Goods Sold | P5: COGS | Q5: -1 | S5: 2024 Start | T5: =EDATE(T3,12) -> 45292 | Y5: Gross Profit | Z5: 1
B6: Sales & Marketing | D6: Payroll | F6: General & Administrative | L6: YTD | N6: Web Domain & Hosting Fees | O6: Cost of Goods Sold | P6: COGS | Q6: -1 | S6: 2024 End | T6: =EDATE(T4,12) -> 45657 | Y6: Expenses | Z6: -1
D7: Advertising | F7: Research & Development | L7: Current Month | N7: Merchant Account Fees | O7: Cost of Goods Sold | P7: COGS | Q7: -1 | S7: 2025 Start | T7: =EDATE(T5,12) -> 45658 | Y7: EBITDA | Z7: 1
D8: Professional Fees | F8: Sales & Marketing | L8: Trailing 3 Months | N8: Gross Profit | O8: Gross Profit | P8: Gross Profit | Q8: 1 | S8: 2025 End | T8: =EDATE(T6,12) -> 46022 | Y8: Other Income | Z8: 1
D9: Other G&A | F9: Customer Support | L9: Trailing 6 Months | N9: Expenses | O9: Expenses | P9: Other G&A | Q9: -1 | S9: Current Month Start | T9: =EOMONTH(CurrentMonth,-1)+1 -> 45474 | Y9: Other Expenses | Z9: -1
D10: EBITDA | F10: EBITDA | L10: Trailing 12 Months | N10: Advertising & Marketing | O10: Expenses | P10: Advertising | Q10: -1 | S10: Current Month End | T10: =CurrentMonth -> 45504 | Y10: Net Other Income | Z10: 1
D11: Net Other Income | F11: Net Other Income | N11: Bank Charges & Fees | O11: Expenses | P11: Other G&A | Q11: -1 | S11: Trailing 3 Mo Start | T11: =EOMONTH(CurrentMonth,-3)+1 -> 45413 | Y11: Net Income | Z11: 1
D12: Net Income | F12: Net Income | N12: Conferences & Events | O12: Expenses | P12: Advertising | Q12: -1 | S12: Trailing 3 mo End | T12: =EOMONTH(T11,2) -> 45504
D13: Number of Hires | N13: Software & Apps | O13: Expenses | P13: Other G&A | Q13: -1 | S13: Trailing 6 Mo Start | T13: =EOMONTH(T11,-4)+1 -> 45323
N14: Insurance | O14: Expenses | P14: Other G&A | Q14: -1 | S14: Trailing 6 Mo End | T14: =EOMONTH(T13,5) -> 45504
N15: Office Expenses | O15: Expenses | P15: Other G&A | Q15: -1 | S15: Trailing 12 Mo Start | T15: =EDATE(T9,-11) -> 45139
N16: Office Supplies | O16: Expenses | P16: Other G&A | Q16: -1 | S16: Trailing 12 Mo End | T16: =EOMONTH(T15,11) -> 45504
N17: Rent & Lease | O17: Expenses | P17: Other G&A | Q17: -1 | S17: YTD Start | T17: =DATE(YEAR(CurrentMonth),1,1) -> 45292
N18: Utilities | O18: Expenses | P18: Other G&A | Q18: -1 | S18: YTD End | T18: =CurrentMonth -> 45504
N19: Professional Services | O19: Expenses | P19: Professional Fees | Q19: -1 | S19: ="Prior Period "&S9 -> Prior Period Current Month Start | T19: =EDATE(T9,-1) -> 45444
N20: Accounting Fees | O20: Expenses | P20: Professional Fees | Q20: -1 | S20: ="Prior Period "&S10 -> Prior Period Current Month End | T20: =EDATE(CurrentMonth,-1) -> 45473
N21: Consulting Fees | O21: Expenses | P21: Professional Fees | Q21: -1 | S21: ="Prior Period "&S11 -> Prior Period Trailing 3 Mo Start | T21: =EDATE(T11,-3) -> 45323
N22: Legal Fees | O22: Expenses | P22: Professional Fees | Q22: -1 | S22: ="Prior Period "&S12 -> Prior Period Trailing 3 mo End | T22: =EDATE(T12,-3) -> 45412
N23: Recruiting Fees | O23: Expenses | P23: Professional Fees | Q23: -1 | S23: ="Prior Period "&S13 -> Prior Period Trailing 6 Mo Start | T23: =EDATE(T13,-6) -> 45139
N24: Payroll Expenses | O24: Expenses | P24: Payroll | Q24: -1 | S24: ="Prior Period "&S14 -> Prior Period Trailing 6 Mo End | T24: =EDATE(T14,-6) -> 45322
N25: Salary & Wages | O25: Expenses | P25: Payroll | Q25: -1 | S25: ="Prior Period "&S15 -> Prior Period Trailing 12 Mo Start | T25: =EDATE(T15,-12) -> 44774
N26: Payroll Taxes | O26: Expenses | P26: Payroll | Q26: -1 | S26: ="Prior Period "&S16 -> Prior Period Trailing 12 Mo End | T26: =EDATE(T16,-12) -> 45138
N27: Health Insurance | O27: Expenses | P27: Payroll | Q27: -1 | S27: ="Prior Period "&S17 -> Prior Period YTD Start | T27: =EOMONTH(T28,-(MONTH(T18)-MONTH(T17)+1))+1 -> 45078
N28: Payroll Processing Fees | O28: Expenses | P28: Payroll | Q28: -1 | S28: ="Prior Period "&S18 -> Prior Period YTD End | T28: =EOMONTH(T17,-1) -> 45291
N29: Commissions Expense | O29: Expenses | P29: Payroll | Q29: -1 | S29: ="Prior Year "&S9 -> Prior Year Current Month Start | T29: =EDATE(T9,-12) -> 45108
N30: Taxes & Licenses | O30: Expenses | P30: Other G&A | Q30: -1 | S30: ="Prior Year "&S10 -> Prior Year Current Month End | T30: =EDATE(CurrentMonth,-12) -> 45138
N31: Travel, Meals & Entertainment | O31: Expenses | P31: Other G&A | Q31: -1 | S31: ="Prior Year "&S11 -> Prior Year Trailing 3 Mo Start | T31: =EDATE(T11,-12) -> 45047
N32: Lodging | O32: Expenses | P32: Other G&A | Q32: -1 | S32: ="Prior Year "&S12 -> Prior Year Trailing 3 mo End | T32: =EDATE(T12,-12) -> 45138
N33: Meals & Entertainment | O33: Expenses | P33: Other G&A | Q33: -1 | S33: ="Prior Year "&S13 -> Prior Year Trailing 6 Mo Start | T33: =EDATE(T13,-12) -> 44958
N34: Travel | O34: Expenses | P34: Other G&A | Q34: -1 | S34: ="Prior Year "&S14 -> Prior Year Trailing 6 Mo End | T34: =EDATE(T14,-12) -> 45138
N35: Net Operating Income | O35: EBITDA | P35: EBITDA | Q35: 1 | S35: ="Prior Year "&S15 -> Prior Year Trailing 12 Mo Start | T35: =EDATE(T15,-12) -> 44774
N36: Other Income | O36: Other Income | P36: Other Income | Q36: 1 | S36: ="Prior Year "&S16 -> Prior Year Trailing 12 Mo End | T36: =EDATE(T16,-12) -> 45138
N37: Interest Income | O37: Other Income | P37: Other Income | Q37: 1 | S37: ="Prior Year "&S17 -> Prior Year YTD Start | T37: =EDATE(T17,-12) -> 44927
N38: Other Expenses | O38: Other Expenses | P38: Other Expenses | Q38: -1 | S38: ="Prior Year "&S18 -> Prior Year YTD End | T38: =EDATE(T18,-12) -> 45138
N39: Depreciation Expense | O39: Other Expenses | P39: Other Expenses | Q39: -1
N40: Interest Expense | O40: Other Expenses | P40: Other Expenses | Q40: -1
N41: Net Other Income | O41: =Mappings[[#This Row],[Account]] -> Net Other Income | P41: Net Other Income | Q41: 1
...

Sheet G&A
A1: Income Statement
A2: Your CFO Guy
A3: General & Admnistrative
C4: Growth | E4: 44957 | F4: =EOMONTH(E4,1) -> 44985 | G4: =EOMONTH(F4,1) -> 45016 | H4: =EOMONTH(G4,1) -> 45046 | I4: =EOMONTH(H4,1) -> 45077 | J4: =EOMONTH(I4,1) -> 45107 | K4: =EOMONTH(J4,1) -> 45138 | L4: =EOMONTH(K4,1) -> 45169 | M4: =EOMONTH(L4,1) -> 45199 | ... AN4: =EOMONTH(AM4,1) -> 46022
B5: Revenue
B6: Sales | C6: 0.03 | E6: 100000 | F6: =E6*(1+$C6) -> 103000 | G6: =F6*(0.97) -> 99910 | H6: =G6*(1+$C6) -> 102907.3 | I6: =H6*(0.97) -> 99820.081 | J6: =I6*(1+$C6) -> 102814.68 | K6: =J6*(1+$C6) -> 105899.12 | L6: =K6*(0.97) -> 102722.15 | M6: =L6*(1+$C6) -> 105803.81 | N6: =M6*(1+$C6) -> 108977.93 | O6: =N6*(1+$C6) -> 112247.27 | P6: =O6*(0.97) -> 108879.85 | Q6: =P6*(1+$C6) -> 112146.24 | R6: =Q6*(1+$C6) -> 115510.63 | S6: =R6*(0.97) -> 112045.31 | T6: =S6*(1+$C6) -> 115406.67 | U6: =T6*(0.97) -> 111944.47 | V6: =U6*(1+$C6) -> 115302.81 | W6: =V6*(1+$C6) -> 118761.89 | X6: =W6*(0.97) -> 115199.03 | Y6: =X6*(0.97) -> 111743.06 | Z6: =Y6*(1+$C6) -> 115095.35 | AA6: =Z6*(1+$C6) -> 118548.22 | AB6: =AA6*(1+$C6) -> 122104.66 | AC6: =AB6*(0.97) -> 118441.52 | AD6: =AC6*(1+$C6) -> 121994.77 | AE6: =AD6*(1+$C6) -> 125654.61 | AF6: =AE6*(1+$C6) -> 129424.25 | AG6: =AF6*(0.97) -> 125541.52 | AH6: =AG6*(1+$C6) -> 129307.77 | AI6: =AH6*(1+$C6) -> 133187 | AJ6: =AI6*(0.97) -> 129191.39 | AK6: =AJ6*(1+$C6) -> 133067.13 | AL6: =AK6*(1+$C6) -> 137059.15 | AM6: =AL6*(1+$C6) -> 141170.92 | AN6: =AM6*(0.97) -> 136935.79
B7: Total Revenue | E7: =SUM(E6 + E5) -> 100000 | F7: =SUM(F6 + F5) -> 103000 | G7: =SUM(G6 + G5) -> 99910 | H7: =SUM(H6 + H5) -> 102907.3 | I7: =SUM(I6 + I5) -> 99820.081 | J7: =SUM(J6 + J5) -> 102814.68 | K7: =SUM(K6 + K5) -> 105899.12 | L7: =SUM(L6 + L5) -> 102722.15 | ... AN7: =SUM(AN6 + AN5) -> 136935.79
B8: Cost of Goods Sold
B9: Web Domain & Hosting Fees | E9: 25000 | F9: 30900 | G9: 13987.4 | H9: 27784.971 | I9: 19964.016 | J9: 13365.909 | K9: 22238.816 | L9: 12326.658 | M9: 17986.649 | N9: 20705.807 | O9: 20204.508 | P9: 13065.582 | Q9: 13457.549 | R9: 20791.914 | S9: 15686.344 | T9: 27697.601 | U9: 19030.56 | V9: 21907.533 | W9: 15439.046 | X9: 25343.787 | Y9: 14526.598 | Z9: 11509.535 | AA9: 21338.679 | AB9: 18315.699 | AC9: 15397.398 | AD9: 25618.901 | AE9: 23874.376 | AF9: 38827.275 | AG9: 37662.456 | AH9: 28447.709 | AI9: 38624.23 | AJ9: 25838.278 | AK9: 25282.755 | AL9: 34264.786 | AM9: 22587.347 | AN9: 15062.937
B10: Merchant Account Fees | C10: 0.1 | E10: 250 | F10: =E10*(1+$C10) -> 275 | G10: =F10*(1+$C10) -> 302.5 | H10: =G10*(1+$C10) -> 332.75 | I10: =H10*(1+$C10) -> 366.025 | J10: =I10*(1+$C10) -> 402.6275 | K10: =J10*(1+$C10) -> 442.89025 | L10: =K10*(1+$C10) -> 487.17928 | M10: =L10*(1+$C10) -> 535.8972 | ... AN10: =AM10*(1+$C10) -> 7025.6092
B11: Total Cost of Goods Sold | E11: =SUM(E10, E9 + E8) -> 25250 | F11: =SUM(F10, F9 + F8) -> 31175 | G11: =SUM(G10, G9 + G8) -> 14289.9 | H11: =SUM(H10, H9 + H8) -> 28117.721 | I11: =SUM(I10, I9 + I8) -> 20330.041 | J11: =SUM(J10, J9 + J8) -> 13768.536 | K11: =SUM(K10, K9 + K8) -> 22681.706 | L11: =SUM(L10, L9 + L8) -> 12813.837 | ... AN11: =SUM(AN10, AN9 + AN8) -> 22088.546
B12: Gross Profit | E12: =E7-E11 -> 74750 | F12: =F7-F11 -> 71825 | G12: =G7-G11 -> 85620.1 | H12: =H7-H11 -> 74789.579 | I12: =I7-I11 -> 79490.04 | J12: =J7-J11 -> 89046.147 | K12: =K7-K11 -> 83217.418 | L12: =L7-L11 -> 89908.313 | ... AN12: =AN7-AN11 -> 114847.25
B13: Expenses
B14: Advertising & Marketing | C14: 0 | E14: 0 | F14: 0 | G14: 0 | H14: 0 | I14: 0 | J14: 0 | K14: 0 | L14: 0 | M14: 0 | N14: 0 | O14: 0 | P14: 0 | Q14: 0 | R14: 0 | S14: 0 | T14: 0 | U14: 0 | V14: 0 | W14: 0 | X14: 0 | Y14: 0 | Z14: 0 | AA14: 0 | AB14: 0 | AC14: 0 | AD14: 0 | AE14: 0 | AF14: 0 | AG14: 0 | AH14: 0 | AI14: 0 | AJ14: 0 | AK14: 0 | AL14: 0 | AM14: 0 | AN14: 0
B15: Bank Charges & Fees | C15: 0.03 | E15: 350 | F15: =E15*(1+$C15) -> 360.5 | G15: =F15*(0.98) -> 353.29 | H15: =G15*(1+$C15) -> 363.8887 | I15: =H15*(1+$C15) -> 374.80536 | J15: =I15*(0.98) -> 367.30925 | K15: =J15*(1+$C15) -> 378.32853 | L15: =K15*(1+$C15) -> 389.67839 | M15: =L15*(1+$C15) -> 401.36874 | N15: =M15*(0.98) -> 393.34136 | O15: =N15*(1+$C15) -> 405.14161 | P15: =O15*(1+$C15) -> 417.29585 | Q15: =P15*(1+$C15) -> 429.81473 | R15: =Q15*(0.98) -> 421.21843 | S15: =R15*(1+$C15) -> 433.85499 | T15: =S15*(1+$C15) -> 446.87064 | U15: =T15*(1+$C15) -> 460.27676 | V15: =U15*(0.98) -> 451.07122 | W15: =V15*(1+$C15) -> 464.60336 | X15: =W15*(1+$C15) -> 478.54146 | Y15: =X15*(0.98) -> 468.97063 | Z15: =Y15*(1+$C15) -> 483.03975 | AA15: =Z15*(1+$C15) -> 497.53094 | AB15: =AA15*(0.98) -> 487.58032 | AC15: =AB15*(1+$C15) -> 502.20773 | AD15: =AC15*(0.98) -> 492.16358 | AE15: =AD15*(1+$C15) -> 506.92848 | AF15: =AE15*(0.98) -> 496.78991 | AG15: =AF15*(1+$C15) -> 511.69361 | AH15: =AG15*(0.98) -> 501.45974 | AI15: =AH15*(1+$C15) -> 516.50353 | AJ15: =AI15*(1+$C15) -> 531.99864 | AK15: =AJ15*(1+$C15) -> 547.9586 | AL15: =AK15*(0.98) -> 536.99942 | AM15: =AL15*(1+$C15) -> 553.10941 | AN15: =AM15*(1+$C15) -> 569.70269
B16: Conferences & Events | C16: 0.04 | E16: 1000 | F16: =E16*(1+$C16) -> 1040 | G16: =F16*(0.9) -> 936 | H16: =G16*(1+$C16) -> 973.44 | I16: =H16*(1+$C16) -> 1012.3776 | J16: =I16*(0.98) -> 992.13005 | K16: =J16*(1+$C16) -> 1031.8152 | L16: =K16*(1+$C16) -> 1073.0879 | M16: =L16*(1+$C16) -> 1116.0114 | N16: =M16*(0.98) -> 1093.6911 | O16: =N16*(1+$C16) -> 1137.4388 | P16: =O16*(1+$C16) -> 1182.9363 | Q16: =P16*(1+$C16) -> 1230.2538 | R16: =Q16*(0.98) -> 1205.6487 | S16: =R16*(1+$C16) -> 1253.8747 | T16: =S16*(1+$C16) -> 1304.0297 | U16: =T16*(1+$C16) -> 1356.1908 | V16: =U16*(0.98) -> 1329.067 | W16: =V16*(1+$C16) -> 1382.2297 | X16: =W16*(1+$C16) -> 1437.5189 | Y16: =X16*(0.98) -> 1408.7685 | Z16: =Y16*(1+$C16) -> 1465.1193 | AA16: =Z16*(1+$C16) -> 1523.724 | AB16: =AA16*(0.98) -> 1493.2495 | AC16: =AB16*(1+$C16) -> 1552.9795 | AD16: =AC16*(0.98) -> 1521.9199 | AE16: =AD16*(1+$C16) -> 1582.7967 | AF16: =AE16*(0.98) -> 1551.1408 | AG16: =AF16*(1+$C16) -> 1613.1864 | AH16: =AG16*(0.98) -> 1580.9227 | AI16: =AH16*(1+$C16) -> 1644.1596 | AJ16: =AI16*(1+$C16) -> 1709.926 | AK16: =AJ16*(1+$C16) -> 1778.323 | AL16: =AK16*(0.98) -> 1742.7566 | AM16: =AL16*(1+$C16) -> 1812.4668 | AN16: =AM16*(1+$C16) -> 1884.9655
B17: Software & Apps | C17: 0.05 | E17: 4000 | F17: =E17*(1+$C17) -> 4200 | G17: =F17*(0.98) -> 4116 | H17: =G17*(1+$C17) -> 4321.8 | I17: =H17*(1+$C17) -> 4537.89 | J17: =I17*(0.98) -> 4447.1322 | K17: =J17*(1+$C17) -> 4669.4888 | L17: =K17*(1+$C17) -> 4902.9633 | M17: =L17*(1+$C17) -> 5148.1114 | N17: =M17*(0.98) -> 5045.1492 | O17: =N17*(1+$C17) -> 5297.4066 | P17: =O17*(1+$C17) -> 5562.277 | Q17: =P17*(1+$C17) -> 5840.3908 | R17: =Q17*(0.98) -> 5723.583 | S17: =R17*(1+$C17) -> 6009.7622 | T17: =S17*(1+$C17) -> 6310.2503 | U17: =T17*(1+$C17) -> 6625.7628 | V17: =U17*(0.98) -> 6493.2475 | W17: =V17*(1+$C17) -> 6817.9099 | X17: =W17*(1+$C17) -> 7158.8054 | Y17: =X17*(0.98) -> 7015.6293 | Z17: =Y17*(1+$C17) -> 7366.4108 | AA17: =Z17*(1+$C17) -> 7734.7313 | AB17: =AA17*(0.98) -> 7580.0367 | AC17: =AB17*(1+$C17) -> 7959.0385 | AD17: =AC17*(0.98) -> 7799.8577 | AE17: =AD17*(1+$C17) -> 8189.8506 | AF17: =AE17*(0.98) -> 8026.0536 | AG17: =AF17*(1+$C17) -> 8427.3563 | AH17: =AG17*(0.98) -> 8258.8092 | AI17: =AH17*(1+$C17) -> 8671.7496 | AJ17: =AI17*(1+$C17) -> 9105.3371 | AK17: =AJ17*(1+$C17) -> 9560.6039 | AL17: =AK17*(0.98) -> 9369.3919 | AM17: =AL17*(1+$C17) -> 9837.8615 | AN17: =AM17*(1+$C17) -> 10329.755
B18: Insurance | C18: 0.03 | E18: 250 | F18: =E18*(1+$C18) -> 257.5 | G18: =F18*(0.98) -> 252.35 | H18: =G18*(1+$C18) -> 259.9205 | I18: =H18*(1+$C18) -> 267.71812 | J18: =I18*(0.98) -> 262.36375 | K18: =J18*(1+$C18) -> 270.23467 | L18: =K18*(1+$C18) -> 278.34171 | M18: =L18*(1+$C18) -> 286.69196 | N18: =M18*(0.98) -> 280.95812 | O18: =N18*(1+$C18) -> 289.38686 | P18: =O18*(1+$C18) -> 298.06847 | Q18: =P18*(1+$C18) -> 307.01052 | R18: =Q18*(0.98) -> 300.87031 | S18: =R18*(1+$C18) -> 309.89642 | T18: =S18*(1+$C18) -> 319.19331 | U18: =T18*(1+$C18) -> 328.76911 | V18: =U18*(0.98) -> 322.19373 | W18: =V18*(1+$C18) -> 331.85954 | X18: =W18*(1+$C18) -> 341.81533 | Y18: =X18*(0.98) -> 334.97902 | Z18: =Y18*(1+$C18) -> 345.02839 | AA18: =Z18*(1+$C18) -> 355.37924 | AB18: =AA18*(0.98) -> 348.27166 | AC18: =AB18*(1+$C18) -> 358.71981 | AD18: =AC18*(0.98) -> 351.54541 | AE18: =AD18*(1+$C18) -> 362.09177 | AF18: =AE18*(0.98) -> 354.84994 | AG18: =AF18*(1+$C18) -> 365.49544 | AH18: =AG18*(0.98) -> 358.18553 | AI18: =AH18*(1+$C18) -> 368.93109 | AJ18: =AI18*(1+$C18) -> 379.99903 | AK18: =AJ18*(1+$C18) -> 391.399 | AL18: =AK18*(0.98) -> 383.57102 | AM18: =AL18*(1+$C18) -> 395.07815 | AN18: =AM18*(1+$C18) -> 406.93049
B19: Office Expenses | C19: 0.03 | E19: 0 | F19: =E19*(1+$C19) -> 0 | G19: =F19*(0.98) -> 0 | H19: =G19*(1+$C19) -> 0 | I19: =H19*(1+$C19) -> 0 | J19: =I19*(0.98) -> 0 | K19: =J19*(1+$C19) -> 0 | L19: =K19*(1+$C19) -> 0 | M19: =L19*(1+$C19) -> 0 | N19: =M19*(0.98) -> 0 | O19: =N19*(1+$C19) -> 0 | P19: =O19*(1+$C19) -> 0 | Q19: =P19*(1+$C19) -> 0 | R19: =Q19*(0.98) -> 0 | S19: =R19*(1+$C19) -> 0 | T19: =S19*(1+$C19) -> 0 | U19: =T19*(1+$C19) -> 0 | V19: =U19*(0.98) -> 0 | W19: =V19*(1+$C19) -> 0 | X19: =W19*(1+$C19) -> 0 | Y19: =X19*(0.98) -> 0 | Z19: =Y19*(1+$C19) -> 0 | AA19: =Z19*(1+$C19) -> 0 | AB19: =AA19*(0.98) -> 0 | AC19: =AB19*(1+$C19) -> 0 | AD19: =AC19*(0.98) -> 0 | AE19: =AD19*(1+$C19) -> 0 | AF19: =AE19*(0.98) -> 0 | AG19: =AF19*(1+$C19) -> 0 | AH19: =AG19*(0.98) -> 0 | AI19: =AH19*(1+$C19) -> 0 | AJ19: =AI19*(1+$C19) -> 0 | AK19: =AJ19*(1+$C19) -> 0 | AL19: =AK19*(0.98) -> 0 | AM19: =AL19*(1+$C19) -> 0 | AN19: =AM19*(1+$C19) -> 0
B20: Office Supplies | C20: 0.05 | E20: 800 | F20: =E20*(1+$C20) -> 840 | G20: =F20*(0.98) -> 823.2 | H20: =G20*(1+$C20) -> 864.36 | I20: =H20*(1+$C20) -> 907.578 | J20: =I20*(0.98) -> 889.42644 | K20: =J20*(1+$C20) -> 933.89776 | L20: =K20*(1+$C20) -> 980.59265 | M20: =L20*(1+$C20) -> 1029.6223 | N20: =M20*(0.98) -> 1009.0298 | O20: =N20*(1+$C20) -> 1059.4813 | P20: =O20*(1+$C20) -> 1112.4554 | Q20: =P20*(1+$C20) -> 1168.0782 | R20: =Q20*(0.98) -> 1144.7166 | S20: =R20*(1+$C20) -> 1201.9524 | T20: =S20*(1+$C20) -> 1262.0501 | U20: =T20*(1+$C20) -> 1325.1526 | V20: =U20*(0.98) -> 1298.6495 | W20: =V20*(1+$C20) -> 1363.582 | X20: =W20*(1+$C20) -> 1431.7611 | Y20: =X20*(0.98) -> 1403.1259 | Z20: =Y20*(1+$C20) -> 1473.2822 | AA20: =Z20*(1+$C20) -> 1546.9463 | AB20: =AA20*(0.98) -> 1516.0073 | AC20: =AB20*(1+$C20) -> 1591.8077 | AD20: =AC20*(0.98) -> 1559.9715 | AE20: =AD20*(1+$C20) -> 1637.9701 | AF20: =AE20*(0.98) -> 1605.2107 | AG20: =AF20*(1+$C20) -> 1685.4713 | AH20: =AG20*(0.98) -> 1651.7618 | AI20: =AH20*(1+$C20) -> 1734.3499 | AJ20: =AI20*(1+$C20) -> 1821.0674 | AK20: =AJ20*(1+$C20) -> 1912.1208 | AL20: =AK20*(0.98) -> 1873.8784 | AM20: =AL20*(1+$C20) -> 1967.5723 | AN20: =AM20*(1+$C20) -> 2065.9509
B21: Rent & Lease | C21: 0.03 | E21: 3500 | F21: =E21*(1+$C21) -> 3605 | G21: =F21*(0.98) -> 3532.9 | H21: =G21*(1+$C21) -> 3638.887 | I21: =H21*(1+$C21) -> 3748.0536 | J21: =I21*(0.98) -> 3673.0925 | K21: =J21*(1+$C21) -> 3783.2853 | L21: =K21*(1+$C21) -> 3896.7839 | M21: =L21*(1+$C21) -> 4013.6874 | N21: =M21*(0.98) -> 3933.4136 | O21: =N21*(1+$C21) -> 4051.4161 | P21: =O21*(1+$C21) -> 4172.9585 | Q21: =P21*(1+$C21) -> 4298.1473 | R21: =Q21*(0.98) -> 4212.1843 | S21: =R21*(1+$C21) -> 4338.5499 | T21: =S21*(1+$C21) -> 4468.7064 | U21: =T21*(1+$C21) -> 4602.7676 | V21: =U21*(0.98) -> 4510.7122 | W21: =V21*(1+$C21) -> 4646.0336 | X21: =W21*(1+$C21) -> 4785.4146 | Y21: =X21*(0.98) -> 4689.7063 | Z21: =Y21*(1+$C21) -> 4830.3975 | AA21: =Z21*(1+$C21) -> 4975.3094 | AB21: =AA21*(0.98) -> 4875.8032 | AC21: =AB21*(1+$C21) -> 5022.0773 | AD21: =AC21*(0.9) -> 4519.8696 | AE21: =AD21*(0.9) -> 4067.8826 | AF21: =AE21*(0.9) -> 3661.0944 | AG21: =AF21*(0.9) -> 3294.9849 | AH21: =AG21*(0.98) -> 3229.0852 | AI21: =AH21*(1+$C21) -> 3325.9578 | AJ21: =AI21*(1+$C21) -> 3425.7365 | AK21: =AJ21*(1+$C21) -> 3528.5086 | AL21: =AK21*(0.9) -> 3175.6578 | AM21: =AL21*(0.9) -> 2858.092 | AN21: =AM21*(0.9) -> 2572.2828
B22: Utilities | C22: 0.03 | E22: 350 | F22: =E22*(1+$C22) -> 360.5 | G22: =F22*(0.98) -> 353.29 | H22: =G22*(1+$C22) -> 363.8887 | I22: =H22*(1+$C22) -> 374.80536 | J22: =I22*(0.98) -> 367.30925 | K22: =J22*(1+$C22) -> 378.32853 | L22: =K22*(1+$C22) -> 389.67839 | M22: =L22*(1+$C22) -> 401.36874 | N22: =M22*(0.98) -> 393.34136 | O22: =N22*(1+$C22) -> 405.14161 | P22: =O22*(1+$C22) -> 417.29585 | Q22: =P22*(1+$C22) -> 429.81473 | R22: =Q22*(0.98) -> 421.21843 | S22: =R22*(1+$C22) -> 433.85499 | T22: =S22*(1+$C22) -> 446.87064 | U22: =T22*(1+$C22) -> 460.27676 | V22: =U22*(0.98) -> 451.07122 | W22: =V22*(1+$C22) -> 464.60336 | X22: =W22*(1+$C22) -> 478.54146 | Y22: =X22*(0.98) -> 468.97063 | Z22: =Y22*(1+$C22) -> 483.03975 | AA22: =Z22*(1+$C22) -> 497.53094 | AB22: =AA22*(0.98) -> 487.58032 | AC22: =AB22*(1+$C22) -> 502.20773 | AD22: =AC22*(0.98) -> 492.16358 | AE22: =AD22*(1+$C22) -> 506.92848 | AF22: =AE22*(0.98) -> 496.78991 | AG22: =AF22*(1+$C22) -> 511.69361 | AH22: =AG22*(0.98) -> 501.45974 | AI22: =AH22*(1+$C22) -> 516.50353 | AJ22: =AI22*(1+$C22) -> 531.99864 | AK22: =AJ22*(1+$C22) -> 547.9586 | AL22: =AK22*(0.98) -> 536.99942 | AM22: =AL22*(1+$C22) -> 553.10941 | AN22: =AM22*(1+$C22) -> 569.70269
B23: Total Office Expenses | E23: =SUM(E22, E21, E20 + E19) -> 4650 | F23: =SUM(F22, F21, F20 + F19) -> 4805.5 | G23: =SUM(G22, G21, G20 + G19) -> 4709.39 | H23: =SUM(H22, H21, H20 + H19) -> 4867.1357 | I23: =SUM(I22, I21, I20 + I19) -> 5030.437 | J23: =SUM(J22, J21, J20 + J19) -> 4929.8282 | K23: =SUM(K22, K21, K20 + K19) -> 5095.5116 | L23: =SUM(L22, L21, L20 + L19) -> 5267.0549 | ... AN23: =SUM(AN22, AN21, AN20 + AN19) -> 5207.9364
B24: Professional Services | E24: 0 | F24: =E24*(1+$C24) -> 0 | G24: =F24*(0.98) -> 0 | H24: =G24*(1+$C24) -> 0 | I24: =H24*(1+$C24) -> 0 | J24: =I24*(0.98) -> 0 | K24: =J24*(1+$C24) -> 0 | L24: =K24*(1+$C24) -> 0 | M24: =L24*(1+$C24) -> 0 | N24: =M24*(0.98) -> 0 | O24: =N24*(1+$C24) -> 0 | P24: =O24*(1+$C24) -> 0 | Q24: =P24*(1+$C24) -> 0 | R24: =Q24*(0.98) -> 0 | S24: =R24*(1+$C24) -> 0 | T24: =S24*(1+$C24) -> 0 | U24: =T24*(1+$C24) -> 0 | V24: =U24*(0.98) -> 0 | W24: =V24*(1+$C24) -> 0 | X24: =W24*(1+$C24) -> 0 | Y24: =X24*(0.98) -> 0 | Z24: =Y24*(1+$C24) -> 0 | AA24: =Z24*(1+$C24) -> 0 | AB24: =AA24*(0.98) -> 0 | AC24: =AB24*(1+$C24) -> 0 | AD24: =AC24*(0.98) -> 0 | AE24: =AD24*(1+$C24) -> 0 | AF24: =AE24*(0.98) -> 0 | AG24: =AF24*(1+$C24) -> 0 | AH24: =AG24*(0.98) -> 0 | AI24: =AH24*(1+$C24) -> 0 | AJ24: =AI24*(1+$C24) -> 0 | AK24: =AJ24*(1+$C24) -> 0 | AL24: =AK24*(0.98) -> 0 | AM24: =AL24*(1+$C24) -> 0 | AN24: =AM24*(1+$C24) -> 0
B25: Accounting Fees | C25: 0.02 | E25: 1000 | F25: =E25*(1+$C25) -> 1020 | G25: =F25*(0.98) -> 999.6 | H25: =G25*(1+$C25) -> 1019.592 | I25: =H25*(1+$C25) -> 1039.9838 | J25: =I25*(0.98) -> 1019.1842 | K25: =J25*(1+$C25) -> 1039.5678 | L25: =K25*(1+$C25) -> 1060.3592 | M25: =L25*(1+$C25) -> 1081.5664 | N25: =M25*(0.98) -> 1059.9351 | O25: =N25*(1+$C25) -> 1081.1338 | P25: =O25*(1+$C25) -> 1102.7564 | Q25: =P25*(1+$C25) -> 1124.8116 | R25: =Q25*(0.98) -> 1102.3153 | S25: =R25*(1+$C25) -> 1124.3616 | T25: =S25*(1+$C25) -> 1146.8489 | U25: =T25*(1+$C25) -> 1169.7859 | V25: =U25*(0.98) -> 1146.3901 | W25: =V25*(1+$C25) -> 1169.3179 | X25: =W25*(1+$C25) -> 1192.7043 | Y25: =X25*(0.98) -> 1168.8502 | Z25: =Y25*(1+$C25) -> 1192.2272 | AA25: =Z25*(1+$C25) -> 1216.0718 | AB25: =AA25*(0.98) -> 1191.7503 | AC25: =AB25*(1+$C25) -> 1215.5853 | AD25: =AC25*(0.98) -> 1191.2736 | AE25: =AD25*(1+$C25) -> 1215.0991 | AF25: =AE25*(0.98) -> 1190.7971 | AG25: =AF25*(1+$C25) -> 1214.6131 | AH25: =AG25*(0.98) -> 1190.3208 | AI25: =AH25*(1+$C25) -> 1214.1272 | AJ25: =AI25*(1+$C25) -> 1238.4098 | AK25: =AJ25*(1+$C25) -> 1263.1779 | AL25: =AK25*(0.98) -> 1237.9144 | AM25: =AL25*(1+$C25) -> 1262.6727 | AN25: =AM25*(1+$C25) -> 1287.9261
B26: Consulting Fees | C26: 0.03 | E26: 2500 | F26: =E26*(1+$C26) -> 2575 | G26: =F26*(0.98) -> 2523.5 | H26: =G26*(1+$C26) -> 2599.205 | I26: =H26*(1+$C26) -> 2677.1811 | J26: =I26*(0.98) -> 2623.6375 | K26: =J26*(1+$C26) -> 2702.3467 | L26: =K26*(1+$C26) -> 2783.4171 | M26: =L26*(1+$C26) -> 2866.9196 | N26: =M26*(0.98) -> 2809.5812 | O26: =N26*(1+$C26) -> 2893.8686 | P26: =O26*(1+$C26) -> 2980.6847 | Q26: =P26*(1+$C26) -> 3070.1052 | R26: =Q26*(0.98) -> 3008.7031 | S26: =R26*(1+$C26) -> 3098.9642 | T26: =S26*(1+$C26) -> 3191.9331 | U26: =T26*(1+$C26) -> 3287.6911 | V26: =U26*(0.98) -> 3221.9373 | W26: =V26*(1+$C26) -> 3318.5954 | X26: =W26*(1+$C26) -> 3418.1533 | Y26: =X26*(0.98) -> 3349.7902 | Z26: =Y26*(1+$C26) -> 3450.2839 | AA26: =Z26*(1+$C26) -> 3553.7924 | AB26: =AA26*(0.98) -> 3482.7166 | AC26: =AB26*(1+$C26) -> 3587.1981 | AD26: =AC26*(0.98) -> 3515.4541 | AE26: =AD26*(1+$C26) -> 3620.9177 | AF26: =AE26*(0.98) -> 3548.4994 | AG26: =AF26*(1+$C26) -> 3654.9544 | AH26: =AG26*(0.98) -> 3581.8553 | AI26: =AH26*(1+$C26) -> 3689.3109 | AJ26: =AI26*(1+$C26) -> 3799.9903 | AK26: =AJ26*(1+$C26) -> 3913.99 | AL26: =AK26*(0.98) -> 3835.7102 | AM26: =AL26*(1+$C26) -> 3950.7815 | AN26: =AM26*(1+$C26) -> 4069.3049
B27: Legal Fees | C27: 0.03 | E27: 1500 | F27: =E27*(1+$C27) -> 1545 | G27: =F27*(0.98) -> 1514.1 | H27: =G27*(1+$C27) -> 1559.523 | I27: =H27*(1+$C27) -> 1606.3087 | J27: =I27*(0.98) -> 1574.1825 | K27: =J27*(1+$C27) -> 1621.408 | L27: =K27*(1+$C27) -> 1670.0502 | M27: =L27*(1+$C27) -> 1720.1517 | N27: =M27*(0.98) -> 1685.7487 | O27: =N27*(1+$C27) -> 1736.3212 | P27: =O27*(1+$C27) -> 1788.4108 | Q27: =P27*(1+$C27) -> 1842.0631 | R27: =Q27*(0.98) -> 1805.2219 | S27: =R27*(1+$C27) -> 1859.3785 | T27: =S27*(1+$C27) -> 1915.1599 | U27: =T27*(1+$C27) -> 1972.6147 | V27: =U27*(0.98) -> 1933.1624 | W27: =V27*(1+$C27) -> 1991.1572 | X27: =W27*(1+$C27) -> 2050.892 | Y27: =X27*(0.98) -> 2009.8741 | Z27: =Y27*(1+$C27) -> 2070.1703 | AA27: =Z27*(1+$C27) -> 2132.2755 | AB27: =AA27*(0.98) -> 2089.6299 | AC27: =AB27*(1+$C27) -> 2152.3188 | AD27: =AC27*(0.98) -> 2109.2725 | AE27: =AD27*(1+$C27) -> 2172.5506 | AF27: =AE27*(0.98) -> 2129.0996 | AG27: =AF27*(1+$C27) -> 2192.9726 | AH27: =AG27*(0.98) -> 2149.1132 | AI27: =AH27*(1+$C27) -> 2213.5866 | AJ27: =AI27*(1+$C27) -> 2279.9942 | AK27: =AJ27*(1+$C27) -> 2348.394 | AL27: =AK27*(0.98) -> 2301.4261 | AM27: =AL27*(1+$C27) -> 2370.4689 | AN27: =AM27*(1+$C27) -> 2441.583
B28: Recruiting Fees | C28: 0.03 | E28: 2000 | F28: =E28*(1+$C28) -> 2060 | G28: =F28*(0.98) -> 2018.8 | H28: =G28*(1+$C28) -> 2079.364 | I28: =H28*(1+$C28) -> 2141.7449 | J28: =I28*(0.98) -> 2098.91 | K28: =J28*(1+$C28) -> 2161.8773 | L28: =K28*(1+$C28) -> 2226.7336 | M28: =L28*(1+$C28) -> 2293.5357 | N28: =M28*(0.98) -> 2247.6649 | O28: =N28*(1+$C28) -> 2315.0949 | P28: =O28*(1+$C28) -> 2384.5477 | Q28: =P28*(1+$C28) -> 2456.0842 | R28: =Q28*(0.98) -> 2406.9625 | S28: =R28*(1+$C28) -> 2479.1714 | T28: =S28*(1+$C28) -> 2553.5465 | U28: =T28*(1+$C28) -> 2630.1529 | V28: =U28*(0.98) -> 2577.5498 | W28: =V28*(1+$C28) -> 2654.8763 | X28: =W28*(1+$C28) -> 2734.5226 | Y28: =X28*(0.98) -> 2679.8322 | Z28: =Y28*(1+$C28) -> 2760.2271 | AA28: =Z28*(1+$C28) -> 2843.0339 | AB28: =AA28*(0.98) -> 2786.1733 | AC28: =AB28*(1+$C28) -> 2869.7585 | AD28: =AC28*(0.98) -> 2812.3633 | AE28: =AD28*(1+$C28) -> 2896.7342 | AF28: =AE28*(0.98) -> 2838.7995 | AG28: =AF28*(1+$C28) -> 2923.9635 | AH28: =AG28*(0.98) -> 2865.4842 | AI28: =AH28*(1+$C28) -> 2951.4488 | AJ28: =AI28*(1+$C28) -> 3039.9922 | AK28: =AJ28*(1+$C28) -> 3131.192 | AL28: =AK28*(0.98) -> 3068.5681 | AM28: =AL28*(1+$C28) -> 3160.6252 | AN28: =AM28*(1+$C28) -> 3255.4439
B29: Total Professional Services | E29: =SUM(E28, E27, E26, E25 + E24) -> 7000 | F29: =SUM(F28, F27, F26, F25 + F24) -> 7200 | G29: =SUM(G28, G27, G26, G25 + G24) -> 7056 | H29: =SUM(H28, H27, H26, H25 + H24) -> 7257.684 | I29: =SUM(I28, I27, I26, I25 + I24) -> 7465.2186 | J29: =SUM(J28, J27, J26, J25 + J24) -> 7315.9142 | K29: =SUM(K28, K27, K26, K25 + K24) -> 7525.1998 | L29: =SUM(L28, L27, L26, L25 + L24) -> 7740.5601 | ... AN29: =SUM(AN28, AN27, AN26, AN25 + AN24) -> 11054.258
B30: Payroll Expenses | C30: 0.03 | E30: 0 | F30: =E30*(1+$C30) -> 0 | G30: =F30*(0.98) -> 0 | H30: =G30*(1+$C30) -> 0 | I30: =H30*(1+$C30) -> 0 | J30: =I30*(0.98) -> 0 | K30: =J30*(1+$C30) -> 0 | L30: =K30*(1+$C30) -> 0 | M30: =L30*(1+$C30) -> 0 | N30: =M30*(0.98) -> 0 | O30: =N30*(1+$C30) -> 0 | P30: =O30*(1+$C30) -> 0 | Q30: =P30*(1+$C30) -> 0 | R30: =Q30*(0.98) -> 0 | S30: =R30*(1+$C30) -> 0 | T30: =S30*(1+$C30) -> 0 | U30: =T30*(1+$C30) -> 0 | V30: =U30*(0.98) -> 0 | W30: =V30*(1+$C30) -> 0 | X30: =W30*(1+$C30) -> 0 | Y30: =X30*(0.98) -> 0 | Z30: =Y30*(1+$C30) -> 0 | AA30: =Z30*(1+$C30) -> 0 | AB30: =AA30*(0.98) -> 0 | AC30: =AB30*(1+$C30) -> 0 | AD30: =AC30*(0.98) -> 0 | AE30: =AD30*(1+$C30) -> 0 | AF30: =AE30*(0.98) -> 0 | AG30: =AF30*(1+$C30) -> 0 | AH30: =AG30*(0.98) -> 0 | AI30: =AH30*(1+$C30) -> 0 | AJ30: =AI30*(1+$C30) -> 0 | AK30: =AJ30*(1+$C30) -> 0 | AL30: =AK30*(0.98) -> 0 | AM30: =AL30*(1+$C30) -> 0 | AN30: =AM30*(1+$C30) -> 0
B31: Salary & Wages | C31: 0.05 | E31: 5000 | F31: =E31*(1+$C31) -> 5250 | G31: =F31*(0.98) -> 5145 | H31: =G31*(0.9) -> 4630.5 | I31: =H31*(0.9) -> 4167.45 | J31: =I31*(0.9) -> 3750.705 | K31: =J31*(1+$C31) -> 3938.2403 | L31: =K31*(1+$C31) -> 4135.1523 | M31: =L31*(1+$C31) -> 4341.9099 | N31: =M31*(0.98) -> 4255.0717 | O31: =N31*(1+$C31) -> 4467.8253 | P31: =O31*(1+$C31) -> 4691.2165 | Q31: =P31*(1+$C31) -> 4925.7774 | R31: =Q31*(0.98) -> 4827.2618 | S31: =R31*(0.9) -> 4344.5356 | T31: =S31*(0.9) -> 3910.0821 | U31: =T31*(1+$C31) -> 4105.5862 | V31: =U31*(0.98) -> 4023.4744 | W31: =V31*(1+$C31) -> 4224.6482 | X31: =W31*(1+$C31) -> 4435.8806 | Y31: =X31*(0.98) -> 4347.163 | Z31: =Y31*(0.9) -> 3912.4467 | AA31: =Z31*(0.9) -> 3521.202 | AB31: =AA31*(0.9) -> 3169.0818 | AC31: =AB31*(1+$C31) -> 3327.5359 | AD31: =AC31*(0.98) -> 3260.9852 | AE31: =AD31*(1+$C31) -> 3424.0344 | AF31: =AE31*(0.98) -> 3355.5537 | AG31: =AF31*(1+$C31) -> 3523.3314 | AH31: =AG31*(0.9) -> 3170.9983 | AI31: =AH31*(0.9) -> 2853.8985 | AJ31: =AI31*(0.9) -> 2568.5086 | AK31: =AJ31*(1+$C31) -> 2696.934 | AL31: =AK31*(0.98) -> 2642.9954 | AM31: =AL31*(1+$C31) -> 2775.1451 | AN31: =AM31*(1+$C31) -> 2913.9024
B32: Payroll Taxes | C32: 0.03 | E32: 500 | F32: =E32*(1+$C32) -> 515 | G32: =F32*(0.98) -> 504.7 | H32: =G32*(1+$C32) -> 519.841 | I32: =H32*(1+$C32) -> 535.43623 | J32: =I32*(0.98) -> 524.72751 | K32: =J32*(1+$C32) -> 540.46933 | L32: =K32*(1+$C32) -> 556.68341 | M32: =L32*(1+$C32) -> 573.38391 | N32: =M32*(0.98) -> 561.91623 | O32: =N32*(1+$C32) -> 578.77372 | P32: =O32*(1+$C32) -> 596.13693 | Q32: =P32*(1+$C32) -> 614.02104 | R32: =Q32*(0.98) -> 601.74062 | S32: =R32*(1+$C32) -> 619.79284 | T32: =S32*(1+$C32) -> 638.38662 | U32: =T32*(1+$C32) -> 657.53822 | V32: =U32*(0.98) -> 644.38746 | W32: =V32*(1+$C32) -> 663.71908 | X32: =W32*(1+$C32) -> 683.63065 | Y32: =X32*(0.98) -> 669.95804 | Z32: =Y32*(1+$C32) -> 690.05678 | AA32: =Z32*(1+$C32) -> 710.75849 | AB32: =AA32*(0.98) -> 696.54332 | AC32: =AB32*(1+$C32) -> 717.43962 | AD32: =AC32*(0.98) -> 703.09082 | AE32: =AD32*(1+$C32) -> 724.18355 | AF32: =AE32*(0.98) -> 709.69988 | AG32: =AF32*(1+$C32) -> 730.99087 | AH32: =AG32*(0.98) -> 716.37106 | AI32: =AH32*(1+$C32) -> 737.86219 | AJ32: =AI32*(1+$C32) -> 759.99805 | AK32: =AJ32*(1+$C32) -> 782.798 | AL32: =AK32*(0.98) -> 767.14204 | AM32: =AL32*(1+$C32) -> 790.1563 | AN32: =AM32*(1+$C32) -> 813.86099
B33: Health Insurance | C33: 0.03 | E33: 450 | F33: =E33*(1+$C33) -> 463.5 | G33: =F33*(0.98) -> 454.23 | H33: =G33*(1+$C33) -> 467.8569 | I33: =H33*(1+$C33) -> 481.89261 | J33: =I33*(0.98) -> 472.25475 | K33: =J33*(1+$C33) -> 486.4224 | L33: =K33*(1+$C33) -> 501.01507 | M33: =L33*(1+$C33) -> 516.04552 | N33: =M33*(0.98) -> 505.72461 | O33: =N33*(1+$C33) -> 520.89635 | P33: =O33*(1+$C33) -> 536.52324 | Q33: =P33*(1+$C33) -> 552.61894 | R33: =Q33*(0.98) -> 541.56656 | S33: =R33*(1+$C33) -> 557.81356 | T33: =S33*(1+$C33) -> 574.54796 | U33: =T33*(1+$C33) -> 591.7844 | V33: =U33*(0.98) -> 579.94871 | W33: =V33*(1+$C33) -> 597.34717 | X33: =W33*(1+$C33) -> 615.26759 | Y33: =X33*(0.98) -> 602.96224 | Z33: =Y33*(1+$C33) -> 621.0511 | AA33: =Z33*(1+$C33) -> 639.68264 | AB33: =AA33*(0.98) -> 626.88898 | AC33: =AB33*(1+$C33) -> 645.69565 | AD33: =AC33*(0.98) -> 632.78174 | AE33: =AD33*(1+$C33) -> 651.76519 | AF33: =AE33*(0.98) -> 638.72989 | AG33: =AF33*(1+$C33) -> 657.89179 | AH33: =AG33*(0.98) -> 644.73395 | AI33: =AH33*(1+$C33) -> 664.07597 | AJ33: =AI33*(1+$C33) -> 683.99825 | AK33: =AJ33*(1+$C33) -> 704.5182 | AL33: =AK33*(0.98) -> 690.42783 | AM33: =AL33*(1+$C33) -> 711.14067 | AN33: =AM33*(1+$C33) -> 732.47489
B34: Payroll Processing Fees | C34: 0.05 | E34: 50 | F34: =E34*(1+$C34) -> 52.5 | G34: =F34*(0.98) -> 51.45 | H34: =G34*(1+$C34) -> 54.0225 | I34: =H34*(1+$C34) -> 56.723625 | J34: =I34*(0.98) -> 55.589153 | K34: =J34*(1+$C34) -> 58.36861 | L34: =K34*(1+$C34) -> 61.287041 | M34: =L34*(1+$C34) -> 64.351393 | N34: =M34*(0.98) -> 63.064365 | O34: =N34*(1+$C34) -> 66.217583 | P34: =O34*(1+$C34) -> 69.528462 | Q34: =P34*(1+$C34) -> 73.004885 | R34: =Q34*(0.98) -> 71.544788 | S34: =R34*(1+$C34) -> 75.122027 | T34: =S34*(1+$C34) -> 78.878128 | U34: =T34*(1+$C34) -> 82.822035 | V34: =U34*(0.98) -> 81.165594 | W34: =V34*(1+$C34) -> 85.223874 | X34: =W34*(1+$C34) -> 89.485067 | Y34: =X34*(0.98) -> 87.695366 | Z34: =Y34*(1+$C34) -> 92.080134 | AA34: =Z34*(1+$C34) -> 96.684141 | AB34: =AA34*(0.98) -> 94.750458 | AC34: =AB34*(1+$C34) -> 99.487981 | AD34: =AC34*(0.98) -> 97.498222 | AE34: =AD34*(1+$C34) -> 102.37313 | AF34: =AE34*(0.98) -> 100.32567 | AG34: =AF34*(1+$C34) -> 105.34195 | AH34: =AG34*(0.98) -> 103.23511 | AI34: =AH34*(1+$C34) -> 108.39687 | AJ34: =AI34*(1+$C34) -> 113.81671 | AK34: =AJ34*(1+$C34) -> 119.50755 | AL34: =AK34*(0.98) -> 117.1174 | AM34: =AL34*(1+$C34) -> 122.97327 | AN34: =AM34*(1+$C34) -> 129.12193
B35: Commissions Expense | C35: 0.03 | E35: 0 | F35: =E35*(1+$C35) -> 0 | G35: =F35*(0.98) -> 0 | H35: =G35*(1+$C35) -> 0 | I35: =H35*(1+$C35) -> 0 | J35: =I35*(0.98) -> 0 | K35: =J35*(1+$C35) -> 0 | L35: =K35*(1+$C35) -> 0 | M35: =L35*(1+$C35) -> 0 | N35: =M35*(0.98) -> 0 | O35: =N35*(1+$C35) -> 0 | P35: =O35*(1+$C35) -> 0 | Q35: =P35*(1+$C35) -> 0 | R35: =Q35*(0.98) -> 0 | S35: =R35*(1+$C35) -> 0 | T35: =S35*(1+$C35) -> 0 | U35: =T35*(1+$C35) -> 0 | V35: =U35*(0.98) -> 0 | W35: =V35*(1+$C35) -> 0 | X35: =W35*(1+$C35) -> 0 | Y35: =X35*(0.98) -> 0 | Z35: =Y35*(1+$C35) -> 0 | AA35: =Z35*(1+$C35) -> 0 | AB35: =AA35*(0.98) -> 0 | AC35: =AB35*(1+$C35) -> 0 | AD35: =AC35*(0.98) -> 0 | AE35: =AD35*(1+$C35) -> 0 | AF35: =AE35*(0.98) -> 0 | AG35: =AF35*(1+$C35) -> 0 | AH35: =AG35*(0.98) -> 0 | AI35: =AH35*(1+$C35) -> 0 | AJ35: =AI35*(1+$C35) -> 0 | AK35: =AJ35*(1+$C35) -> 0 | AL35: =AK35*(0.98) -> 0 | AM35: =AL35*(1+$C35) -> 0 | AN35: =AM35*(1+$C35) -> 0
B36: Total Payroll Expenses | E36: =SUM(E35, E34, E33, E32, E31 + E30) -> 6000 | F36: =SUM(F35, F34, F33, F32, F31 + F30) -> 6281 | G36: =SUM(G35, G34, G33, G32, G31 + G30) -> 6155.38 | H36: =SUM(H35, H34, H33, H32, H31 + H30) -> 5672.2204 | I36: =SUM(I35, I34, I33, I32, I31 + I30) -> 5241.5025 | J36: =SUM(J35, J34, J33, J32, J31 + J30) -> 4803.2764 | K36: =SUM(K35, K34, K33, K32, K31 + K30) -> 5023.5006 | L36: =SUM(L35, L34, L33, L32, L31 + L30) -> 5254.1378 | ... AN36: =SUM(AN35, AN34, AN33, AN32, AN31 + AN30) -> 4589.3602
B37: Taxes & Licenses | C37: 0.05 | E37: 150 | F37: =E37*(1+$C37) -> 157.5 | G37: =F37*(0.98) -> 154.35 | H37: =G37*(1+$C37) -> 162.0675 | I37: =H37*(1+$C37) -> 170.17087 | J37: =I37*(0.98) -> 166.76746 | K37: =J37*(1+$C37) -> 175.10583 | L37: =K37*(1+$C37) -> 183.86112 | M37: =L37*(1+$C37) -> 193.05418 | N37: =M37*(0.98) -> 189.19309 | O37: =N37*(1+$C37) -> 198.65275 | P37: =O37*(1+$C37) -> 208.58539 | Q37: =P37*(1+$C37) -> 219.01466 | R37: =Q37*(0.98) -> 214.63436 | S37: =R37*(1+$C37) -> 225.36608 | T37: =S37*(1+$C37) -> 236.63439 | U37: =T37*(1+$C37) -> 248.4661 | V37: =U37*(0.98) -> 243.49678 | W37: =V37*(1+$C37) -> 255.67162 | X37: =W37*(1+$C37) -> 268.4552 | Y37: =X37*(0.98) -> 263.0861 | Z37: =Y37*(1+$C37) -> 276.2404 | AA37: =Z37*(1+$C37) -> 290.05242 | AB37: =AA37*(0.98) -> 284.25137 | AC37: =AB37*(1+$C37) -> 298.46394 | AD37: =AC37*(0.98) -> 292.49466 | AE37: =AD37*(1+$C37) -> 307.1194 | AF37: =AE37*(0.98) -> 300.97701 | AG37: =AF37*(1+$C37) -> 316.02586 | AH37: =AG37*(0.98) -> 309.70534 | AI37: =AH37*(1+$C37) -> 325.19061 | AJ37: =AI37*(1+$C37) -> 341.45014 | AK37: =AJ37*(1+$C37) -> 358.52265 | AL37: =AK37*(0.98) -> 351.3522 | AM37: =AL37*(1+$C37) -> 368.9198 | AN37: =AM37*(1+$C37) -> 387.3658
B38: Travel, Meals & Entertainment | C38: 0.03 | E38: 0 | F38: =E38*(1+$C38) -> 0 | G38: =F38*(0.98) -> 0 | H38: =G38*(1+$C38) -> 0 | I38: =H38*(1+$C38) -> 0 | J38: =I38*(0.98) -> 0 | K38: =J38*(1+$C38) -> 0 | L38: =K38*(1+$C38) -> 0 | M38: =L38*(1+$C38) -> 0 | N38: =M38*(0.98) -> 0 | O38: =N38*(1+$C38) -> 0 | P38: =O38*(1+$C38) -> 0 | Q38: =P38*(1+$C38) -> 0 | R38: =Q38*(0.98) -> 0 | S38: =R38*(1+$C38) -> 0 | T38: =S38*(1+$C38) -> 0 | U38: =T38*(1+$C38) -> 0 | V38: =U38*(0.98) -> 0 | W38: =V38*(1+$C38) -> 0 | X38: =W38*(1+$C38) -> 0 | Y38: =X38*(0.98) -> 0 | Z38: =Y38*(1+$C38) -> 0 | AA38: =Z38*(1+$C38) -> 0 | AB38: =AA38*(0.98) -> 0 | AC38: =AB38*(1+$C38) -> 0 | AD38: =AC38*(0.98) -> 0 | AE38: =AD38*(1+$C38) -> 0 | AF38: =AE38*(0.98) -> 0 | AG38: =AF38*(1+$C38) -> 0 | AH38: =AG38*(0.98) -> 0 | AI38: =AH38*(1+$C38) -> 0 | AJ38: =AI38*(1+$C38) -> 0 | AK38: =AJ38*(1+$C38) -> 0 | AL38: =AK38*(0.98) -> 0 | AM38: =AL38*(1+$C38) -> 0 | AN38: =AM38*(1+$C38) -> 0
B39: Lodging | C39: 0.03 | E39: 1000 | F39: =E39*(1+$C39) -> 1030 | G39: =F39*(0.98) -> 1009.4 | H39: =G39*(1+$C39) -> 1039.682 | I39: =H39*(1+$C39) -> 1070.8725 | J39: =I39*(0.98) -> 1049.455 | K39: =J39*(1+$C39) -> 1080.9387 | L39: =K39*(1+$C39) -> 1113.3668 | M39: =L39*(1+$C39) -> 1146.7678 | N39: =M39*(0.98) -> 1123.8325 | O39: =N39*(1+$C39) -> 1157.5474 | P39: =O39*(1+$C39) -> 1192.2739 | Q39: =P39*(1+$C39) -> 1228.0421 | R39: =Q39*(0.98) -> 1203.4812 | S39: =R39*(1+$C39) -> 1239.5857 | T39: =S39*(1+$C39) -> 1276.7732 | U39: =T39*(1+$C39) -> 1315.0764 | V39: =U39*(0.98) -> 1288.7749 | W39: =V39*(1+$C39) -> 1327.4382 | X39: =W39*(1+$C39) -> 1367.2613 | Y39: =X39*(0.98) -> 1339.9161 | Z39: =Y39*(1+$C39) -> 1380.1136 | AA39: =Z39*(1+$C39) -> 1421.517 | AB39: =AA39*(0.98) -> 1393.0866 | AC39: =AB39*(1+$C39) -> 1434.8792 | AD39: =AC39*(0.98) -> 1406.1816 | AE39: =AD39*(1+$C39) -> 1448.3671 | AF39: =AE39*(0.98) -> 1419.3998 | AG39: =AF39*(1+$C39) -> 1461.9817 | AH39: =AG39*(0.98) -> 1432.7421 | AI39: =AH39*(1+$C39) -> 1475.7244 | AJ39: =AI39*(1+$C39) -> 1519.9961 | AK39: =AJ39*(1+$C39) -> 1565.596 | AL39: =AK39*(0.98) -> 1534.2841 | AM39: =AL39*(1+$C39) -> 1580.3126 | AN39: =AM39*(1+$C39) -> 1627.722
B40: Meals & Entertainment | C40: 0.05 | E40: 400 | F40: =E40*(1+$C40) -> 420 | G40: =F40*(0.98) -> 411.6 | H40: =G40*(1+$C40) -> 432.18 | I40: =H40*(1+$C40) -> 453.789 | J40: =I40*(0.98) -> 444.71322 | K40: =J40*(1+$C40) -> 466.94888 | L40: =K40*(1+$C40) -> 490.29633 | M40: =L40*(1+$C40) -> 514.81114 | N40: =M40*(0.98) -> 504.51492 | O40: =N40*(1+$C40) -> 529.74066 | P40: =O40*(1+$C40) -> 556.2277 | Q40: =P40*(1+$C40) -> 584.03908 | R40: =Q40*(0.98) -> 572.3583 | S40: =R40*(1+$C40) -> 600.97622 | T40: =S40*(1+$C40) -> 631.02503 | U40: =T40*(1+$C40) -> 662.57628 | V40: =U40*(0.98) -> 649.32475 | W40: =V40*(1+$C40) -> 681.79099 | X40: =W40*(1+$C40) -> 715.88054 | Y40: =X40*(0.98) -> 701.56293 | Z40: =Y40*(1+$C40) -> 736.64108 | AA40: =Z40*(1+$C40) -> 773.47313 | AB40: =AA40*(0.98) -> 758.00367 | AC40: =AB40*(1+$C40) -> 795.90385 | AD40: =AC40*(0.98) -> 779.98577 | AE40: =AD40*(1+$C40) -> 818.98506 | AF40: =AE40*(0.98) -> 802.60536 | AG40: =AF40*(1+$C40) -> 842.73563 | AH40: =AG40*(0.98) -> 825.88092 | AI40: =AH40*(1+$C40) -> 867.17496 | AJ40: =AI40*(1+$C40) -> 910.53371 | AK40: =AJ40*(1+$C40) -> 956.06039 | AL40: =AK40*(0.98) -> 936.93919 | AM40: =AL40*(1+$C40) -> 983.78615 | AN40: =AM40*(1+$C40) -> 1032.9755
...

Sheet R&D
A1: Income Statement
A2: Your CFO Guy
A3: Research & Development
C4: Growth | E4: 44957 | F4: =EOMONTH(E4,1) -> 44985 | G4: =EOMONTH(F4,1) -> 45016 | H4: =EOMONTH(G4,1) -> 45046 | I4: =EOMONTH(H4,1) -> 45077 | J4: =EOMONTH(I4,1) -> 45107 | K4: =EOMONTH(J4,1) -> 45138 | L4: =EOMONTH(K4,1) -> 45169 | M4: =EOMONTH(L4,1) -> 45199 | ... AN4: =EOMONTH(AM4,1) -> 46022
B5: Revenue
B6: Sales | C6: 0.1 | E6: 0 | F6: 0 | G6: 0 | H6: 0 | I6: 0 | J6: 0 | K6: 0 | L6: 0 | M6: 0 | N6: 0 | O6: 0 | P6: 0 | Q6: 0 | R6: 0 | S6: 0 | T6: 0 | U6: 0 | V6: 0 | W6: 0 | X6: 0 | Y6: 0 | Z6: 0 | AA6: 0 | AB6: 0 | AC6: 0 | AD6: 0 | AE6: 0 | AF6: 0 | AG6: 0 | AH6: 0 | AI6: 0 | AJ6: 0 | AK6: 0 | AL6: 0 | AM6: 0 | AN6: 0
B7: Total Revenue | E7: =SUM(E6 + E5) -> 0 | F7: =SUM(F6 + F5) -> 0 | G7: =SUM(G6 + G5) -> 0 | H7: =SUM(H6 + H5) -> 0 | I7: =SUM(I6 + I5) -> 0 | J7: =SUM(J6 + J5) -> 0 | K7: =SUM(K6 + K5) -> 0 | L7: =SUM(L6 + L5) -> 0 | ... AN7: =SUM(AN6 + AN5) -> 0
B8: Cost of Goods Sold
B9: Web Domain & Hosting Fees | C9: 0.1 | E9: 0 | F9: 0 | G9: 0 | H9: 0 | I9: 0 | J9: 0 | K9: 0 | L9: 0 | M9: 0 | N9: 0 | O9: 0 | P9: 0 | Q9: 0 | R9: 0 | S9: 0 | T9: 0 | U9: 0 | V9: 0 | W9: 0 | X9: 0 | Y9: 0 | Z9: 0 | AA9: 0 | AB9: 0 | AC9: 0 | AD9: 0 | AE9: 0 | AF9: 0 | AG9: 0 | AH9: 0 | AI9: 0 | AJ9: 0 | AK9: 0 | AL9: 0 | AM9: 0 | AN9: 0
B10: Merchant Account Fees | C10: 0.1 | E10: 0 | F10: 0 | G10: 0 | H10: 0 | I10: 0 | J10: 0 | K10: 0 | L10: 0 | M10: 0 | N10: 0 | O10: 0 | P10: 0 | Q10: 0 | R10: 0 | S10: 0 | T10: 0 | U10: 0 | V10: 0 | W10: 0 | X10: 0 | Y10: 0 | Z10: 0 | AA10: 0 | AB10: 0 | AC10: 0 | AD10: 0 | AE10: 0 | AF10: 0 | AG10: 0 | AH10: 0 | AI10: 0 | AJ10: 0 | AK10: 0 | AL10: 0 | AM10: 0 | AN10: 0
